Exit code: 1
Stdout:

Stderr:
[I 2024-11-04 12:27:47,030] A new study created in memory with name: no-name-0dc4e1b3-f6c1-4b05-8d54-5d3a62386a72
[W 2024-11-04 12:27:47,066] Trial 0 failed with parameters: {'operator1': 'local_random_walk', 'probability': 0.6156074183093424, 'scale': 0.3986758074262394, 'distribution': 'uniform', 'selector1': 'metropolis', 'operator2': 'local_random_walk', 'radius': 0.24717004682133067, 'angle': 129.05756104108121, 'sigma': 0.5112168221818202, 'selector2': 'probabilistic'} because of the following error: TypeError("local_random_walk() got an unexpected keyword argument 'radius'").
joblib.externals.loky.process_executor._RemoteTraceback: 
"""
Traceback (most recent call last):
  File "/Users/valeriaenriquezlimon/Documents/research-llm/.venv/lib/python3.12/site-packages/joblib/_utils.py", line 72, in __call__
    return self.func(**kwargs)
           ^^^^^^^^^^^^^^^^^^^
  File "/Users/valeriaenriquezlimon/Documents/research-llm/.venv/lib/python3.12/site-packages/joblib/parallel.py", line 598, in __call__
    return [func(*args, **kwargs)
            ^^^^^^^^^^^^^^^^^^^^^
  File "/Users/valeriaenriquezlimon/Documents/research-llm/llm-metaheuristics/ollama_output_20241104_115848/execution_optuna_iteration_1.py", line 25, in run_metaheuristic
    met.run()
  File "/Users/valeriaenriquezlimon/Documents/research-llm/llm-metaheuristics/metaheuristic.py", line 143, in run
    self.apply_search_operator(perturbator, selector)
  File "/Users/valeriaenriquezlimon/Documents/research-llm/llm-metaheuristics/metaheuristic.py", line 99, in apply_search_operator
    exec('Operators.' + operator_name + '(self.pop,' + operator_params)
  File "<string>", line 1, in <module>
TypeError: local_random_walk() got an unexpected keyword argument 'radius'
"""

The above exception was the direct cause of the following exception:

Traceback (most recent call last):
  File "/Users/valeriaenriquezlimon/Documents/research-llm/.venv/lib/python3.12/site-packages/optuna/study/_optimize.py", line 197, in _run_trial
    value_or_values = func(trial)
                      ^^^^^^^^^^^
  File "/Users/valeriaenriquezlimon/Documents/research-llm/llm-metaheuristics/ollama_output_20241104_115848/execution_optuna_iteration_1.py", line 62, in objective
    performance = evaluate_sequence_performance(heur, prob, num_agents=50, num_iterations=100, num_replicas=30)
                  ^^^^^^^^^^^^^^^^^^^^^^^^^^^^^^^^^^^^^^^^^^^^^^^^^^^^^^^^^^^^^^^^^^^^^^^^^^^^^^^^^^^^^^^^^^^^^
  File "/Users/valeriaenriquezlimon/Documents/research-llm/llm-metaheuristics/ollama_output_20241104_115848/execution_optuna_iteration_1.py", line 30, in evaluate_sequence_performance
    results_parallel = Parallel(n_jobs=num_cores)(delayed(run_metaheuristic)() for _ in range(num_replicas))
                       ^^^^^^^^^^^^^^^^^^^^^^^^^^^^^^^^^^^^^^^^^^^^^^^^^^^^^^^^^^^^^^^^^^^^^^^^^^^^^^^^^^^^^
  File "/Users/valeriaenriquezlimon/Documents/research-llm/.venv/lib/python3.12/site-packages/joblib/parallel.py", line 2007, in __call__
    return output if self.return_generator else list(output)
                                                ^^^^^^^^^^^^
  File "/Users/valeriaenriquezlimon/Documents/research-llm/.venv/lib/python3.12/site-packages/joblib/parallel.py", line 1650, in _get_outputs
    yield from self._retrieve()
  File "/Users/valeriaenriquezlimon/Documents/research-llm/.venv/lib/python3.12/site-packages/joblib/parallel.py", line 1754, in _retrieve
    self._raise_error_fast()
  File "/Users/valeriaenriquezlimon/Documents/research-llm/.venv/lib/python3.12/site-packages/joblib/parallel.py", line 1789, in _raise_error_fast
    error_job.get_result(self.timeout)
  File "/Users/valeriaenriquezlimon/Documents/research-llm/.venv/lib/python3.12/site-packages/joblib/parallel.py", line 745, in get_result
    return self._return_or_raise()
           ^^^^^^^^^^^^^^^^^^^^^^^
  File "/Users/valeriaenriquezlimon/Documents/research-llm/.venv/lib/python3.12/site-packages/joblib/parallel.py", line 763, in _return_or_raise
    raise self._result
TypeError: local_random_walk() got an unexpected keyword argument 'radius'
[W 2024-11-04 12:27:47,068] Trial 0 failed with value None.
joblib.externals.loky.process_executor._RemoteTraceback: 
"""
Traceback (most recent call last):
  File "/Users/valeriaenriquezlimon/Documents/research-llm/.venv/lib/python3.12/site-packages/joblib/_utils.py", line 72, in __call__
    return self.func(**kwargs)
           ^^^^^^^^^^^^^^^^^^^
  File "/Users/valeriaenriquezlimon/Documents/research-llm/.venv/lib/python3.12/site-packages/joblib/parallel.py", line 598, in __call__
    return [func(*args, **kwargs)
            ^^^^^^^^^^^^^^^^^^^^^
  File "/Users/valeriaenriquezlimon/Documents/research-llm/llm-metaheuristics/ollama_output_20241104_115848/execution_optuna_iteration_1.py", line 25, in run_metaheuristic
    met.run()
  File "/Users/valeriaenriquezlimon/Documents/research-llm/llm-metaheuristics/metaheuristic.py", line 143, in run
    self.apply_search_operator(perturbator, selector)
  File "/Users/valeriaenriquezlimon/Documents/research-llm/llm-metaheuristics/metaheuristic.py", line 99, in apply_search_operator
    exec('Operators.' + operator_name + '(self.pop,' + operator_params)
  File "<string>", line 1, in <module>
TypeError: local_random_walk() got an unexpected keyword argument 'radius'
"""

The above exception was the direct cause of the following exception:

Traceback (most recent call last):
  File "/Users/valeriaenriquezlimon/Documents/research-llm/llm-metaheuristics/ollama_output_20241104_115848/execution_optuna_iteration_1.py", line 68, in <module>
    study.optimize(objective, n_trials=50) 
    ^^^^^^^^^^^^^^^^^^^^^^^^^^^^^^^^^^^^^^
  File "/Users/valeriaenriquezlimon/Documents/research-llm/.venv/lib/python3.12/site-packages/optuna/study/study.py", line 475, in optimize
    _optimize(
  File "/Users/valeriaenriquezlimon/Documents/research-llm/.venv/lib/python3.12/site-packages/optuna/study/_optimize.py", line 63, in _optimize
    _optimize_sequential(
  File "/Users/valeriaenriquezlimon/Documents/research-llm/.venv/lib/python3.12/site-packages/optuna/study/_optimize.py", line 160, in _optimize_sequential
    frozen_trial = _run_trial(study, func, catch)
                   ^^^^^^^^^^^^^^^^^^^^^^^^^^^^^^
  File "/Users/valeriaenriquezlimon/Documents/research-llm/.venv/lib/python3.12/site-packages/optuna/study/_optimize.py", line 248, in _run_trial
    raise func_err
  File "/Users/valeriaenriquezlimon/Documents/research-llm/.venv/lib/python3.12/site-packages/optuna/study/_optimize.py", line 197, in _run_trial
    value_or_values = func(trial)
                      ^^^^^^^^^^^
  File "/Users/valeriaenriquezlimon/Documents/research-llm/llm-metaheuristics/ollama_output_20241104_115848/execution_optuna_iteration_1.py", line 62, in objective
    performance = evaluate_sequence_performance(heur, prob, num_agents=50, num_iterations=100, num_replicas=30)
                  ^^^^^^^^^^^^^^^^^^^^^^^^^^^^^^^^^^^^^^^^^^^^^^^^^^^^^^^^^^^^^^^^^^^^^^^^^^^^^^^^^^^^^^^^^^^^^
  File "/Users/valeriaenriquezlimon/Documents/research-llm/llm-metaheuristics/ollama_output_20241104_115848/execution_optuna_iteration_1.py", line 30, in evaluate_sequence_performance
    results_parallel = Parallel(n_jobs=num_cores)(delayed(run_metaheuristic)() for _ in range(num_replicas))
                       ^^^^^^^^^^^^^^^^^^^^^^^^^^^^^^^^^^^^^^^^^^^^^^^^^^^^^^^^^^^^^^^^^^^^^^^^^^^^^^^^^^^^^
  File "/Users/valeriaenriquezlimon/Documents/research-llm/.venv/lib/python3.12/site-packages/joblib/parallel.py", line 2007, in __call__
    return output if self.return_generator else list(output)
                                                ^^^^^^^^^^^^
  File "/Users/valeriaenriquezlimon/Documents/research-llm/.venv/lib/python3.12/site-packages/joblib/parallel.py", line 1650, in _get_outputs
    yield from self._retrieve()
  File "/Users/valeriaenriquezlimon/Documents/research-llm/.venv/lib/python3.12/site-packages/joblib/parallel.py", line 1754, in _retrieve
    self._raise_error_fast()
  File "/Users/valeriaenriquezlimon/Documents/research-llm/.venv/lib/python3.12/site-packages/joblib/parallel.py", line 1789, in _raise_error_fast
    error_job.get_result(self.timeout)
  File "/Users/valeriaenriquezlimon/Documents/research-llm/.venv/lib/python3.12/site-packages/joblib/parallel.py", line 745, in get_result
    return self._return_or_raise()
           ^^^^^^^^^^^^^^^^^^^^^^^
  File "/Users/valeriaenriquezlimon/Documents/research-llm/.venv/lib/python3.12/site-packages/joblib/parallel.py", line 763, in _return_or_raise
    raise self._result
TypeError: local_random_walk() got an unexpected keyword argument 'radius'
