Exit code Optuna: 1
Stdout:

Stderr:
[I 2024-10-24 17:56:15,719] A new study created in memory with name: no-name-8a78bac2-19c9-4547-b47d-84a0bd117774
[W 2024-10-24 17:56:17,148] Trial 0 failed with parameters: {'local_random_walk_probability': 0.1817909145782707, 'local_random_walk_scale': 1.7707983613175633, 'local_random_walk_distribution': 'normal'} because of the following error: OperatorsError('Invalid distribution!').
joblib.externals.loky.process_executor._RemoteTraceback: 
"""
Traceback (most recent call last):
  File "/Users/valeriaenriquezlimon/Documents/research-llm/.venv/lib/python3.12/site-packages/joblib/externals/loky/process_executor.py", line 463, in _process_worker
    r = call_item()
        ^^^^^^^^^^^
  File "/Users/valeriaenriquezlimon/Documents/research-llm/.venv/lib/python3.12/site-packages/joblib/externals/loky/process_executor.py", line 291, in __call__
    return self.fn(*self.args, **self.kwargs)
           ^^^^^^^^^^^^^^^^^^^^^^^^^^^^^^^^^^
  File "/Users/valeriaenriquezlimon/Documents/research-llm/.venv/lib/python3.12/site-packages/joblib/parallel.py", line 598, in __call__
    return [func(*args, **kwargs)
            ^^^^^^^^^^^^^^^^^^^^^
  File "/Users/valeriaenriquezlimon/Documents/research-llm/llm-metaheuristics/ollama_output_20241024_175417/execution_optuna_iteration_0.py", line 23, in run_metaheuristic
    met.run()
  File "/Users/valeriaenriquezlimon/Documents/research-llm/llm-metaheuristics/metaheuristic.py", line 143, in run
    self.apply_search_operator(perturbator, selector)
  File "/Users/valeriaenriquezlimon/Documents/research-llm/llm-metaheuristics/metaheuristic.py", line 99, in apply_search_operator
    exec('Operators.' + operator_name + '(self.pop,' + operator_params)
  File "<string>", line 1, in <module>
  File "/Users/valeriaenriquezlimon/Documents/research-llm/llm-metaheuristics/operators.py", line 641, in local_random_walk
    raise OperatorsError('Invalid distribution!')
operators.OperatorsError: Invalid distribution!
"""

The above exception was the direct cause of the following exception:

Traceback (most recent call last):
  File "/Users/valeriaenriquezlimon/Documents/research-llm/.venv/lib/python3.12/site-packages/optuna/study/_optimize.py", line 197, in _run_trial
    value_or_values = func(trial)
                      ^^^^^^^^^^^
  File "/Users/valeriaenriquezlimon/Documents/research-llm/llm-metaheuristics/ollama_output_20241024_175417/execution_optuna_iteration_0.py", line 49, in objective
    performance = evaluate_sequence_performance(heur, prob, num_agents=50, num_iterations=100, num_replicas=30)
                  ^^^^^^^^^^^^^^^^^^^^^^^^^^^^^^^^^^^^^^^^^^^^^^^^^^^^^^^^^^^^^^^^^^^^^^^^^^^^^^^^^^^^^^^^^^^^^
  File "/Users/valeriaenriquezlimon/Documents/research-llm/llm-metaheuristics/ollama_output_20241024_175417/execution_optuna_iteration_0.py", line 28, in evaluate_sequence_performance
    results_parallel = Parallel(n_jobs=num_cores)(delayed(run_metaheuristic)() for _ in range(num_replicas))
                       ^^^^^^^^^^^^^^^^^^^^^^^^^^^^^^^^^^^^^^^^^^^^^^^^^^^^^^^^^^^^^^^^^^^^^^^^^^^^^^^^^^^^^
  File "/Users/valeriaenriquezlimon/Documents/research-llm/.venv/lib/python3.12/site-packages/joblib/parallel.py", line 2007, in __call__
    return output if self.return_generator else list(output)
                                                ^^^^^^^^^^^^
  File "/Users/valeriaenriquezlimon/Documents/research-llm/.venv/lib/python3.12/site-packages/joblib/parallel.py", line 1650, in _get_outputs
    yield from self._retrieve()
  File "/Users/valeriaenriquezlimon/Documents/research-llm/.venv/lib/python3.12/site-packages/joblib/parallel.py", line 1754, in _retrieve
    self._raise_error_fast()
  File "/Users/valeriaenriquezlimon/Documents/research-llm/.venv/lib/python3.12/site-packages/joblib/parallel.py", line 1789, in _raise_error_fast
    error_job.get_result(self.timeout)
  File "/Users/valeriaenriquezlimon/Documents/research-llm/.venv/lib/python3.12/site-packages/joblib/parallel.py", line 745, in get_result
    return self._return_or_raise()
           ^^^^^^^^^^^^^^^^^^^^^^^
  File "/Users/valeriaenriquezlimon/Documents/research-llm/.venv/lib/python3.12/site-packages/joblib/parallel.py", line 763, in _return_or_raise
    raise self._result
operators.OperatorsError: Invalid distribution!
[W 2024-10-24 17:56:17,148] Trial 0 failed with value None.
joblib.externals.loky.process_executor._RemoteTraceback: 
"""
Traceback (most recent call last):
  File "/Users/valeriaenriquezlimon/Documents/research-llm/.venv/lib/python3.12/site-packages/joblib/externals/loky/process_executor.py", line 463, in _process_worker
    r = call_item()
        ^^^^^^^^^^^
  File "/Users/valeriaenriquezlimon/Documents/research-llm/.venv/lib/python3.12/site-packages/joblib/externals/loky/process_executor.py", line 291, in __call__
    return self.fn(*self.args, **self.kwargs)
           ^^^^^^^^^^^^^^^^^^^^^^^^^^^^^^^^^^
  File "/Users/valeriaenriquezlimon/Documents/research-llm/.venv/lib/python3.12/site-packages/joblib/parallel.py", line 598, in __call__
    return [func(*args, **kwargs)
            ^^^^^^^^^^^^^^^^^^^^^
  File "/Users/valeriaenriquezlimon/Documents/research-llm/llm-metaheuristics/ollama_output_20241024_175417/execution_optuna_iteration_0.py", line 23, in run_metaheuristic
    met.run()
  File "/Users/valeriaenriquezlimon/Documents/research-llm/llm-metaheuristics/metaheuristic.py", line 143, in run
    self.apply_search_operator(perturbator, selector)
  File "/Users/valeriaenriquezlimon/Documents/research-llm/llm-metaheuristics/metaheuristic.py", line 99, in apply_search_operator
    exec('Operators.' + operator_name + '(self.pop,' + operator_params)
  File "<string>", line 1, in <module>
  File "/Users/valeriaenriquezlimon/Documents/research-llm/llm-metaheuristics/operators.py", line 641, in local_random_walk
    raise OperatorsError('Invalid distribution!')
operators.OperatorsError: Invalid distribution!
"""

The above exception was the direct cause of the following exception:

Traceback (most recent call last):
  File "/Users/valeriaenriquezlimon/Documents/research-llm/llm-metaheuristics/ollama_output_20241024_175417/execution_optuna_iteration_0.py", line 55, in <module>
    study.optimize(objective, n_trials=50) 
    ^^^^^^^^^^^^^^^^^^^^^^^^^^^^^^^^^^^^^^
  File "/Users/valeriaenriquezlimon/Documents/research-llm/.venv/lib/python3.12/site-packages/optuna/study/study.py", line 475, in optimize
    _optimize(
  File "/Users/valeriaenriquezlimon/Documents/research-llm/.venv/lib/python3.12/site-packages/optuna/study/_optimize.py", line 63, in _optimize
    _optimize_sequential(
  File "/Users/valeriaenriquezlimon/Documents/research-llm/.venv/lib/python3.12/site-packages/optuna/study/_optimize.py", line 160, in _optimize_sequential
    frozen_trial = _run_trial(study, func, catch)
                   ^^^^^^^^^^^^^^^^^^^^^^^^^^^^^^
  File "/Users/valeriaenriquezlimon/Documents/research-llm/.venv/lib/python3.12/site-packages/optuna/study/_optimize.py", line 248, in _run_trial
    raise func_err
  File "/Users/valeriaenriquezlimon/Documents/research-llm/.venv/lib/python3.12/site-packages/optuna/study/_optimize.py", line 197, in _run_trial
    value_or_values = func(trial)
                      ^^^^^^^^^^^
  File "/Users/valeriaenriquezlimon/Documents/research-llm/llm-metaheuristics/ollama_output_20241024_175417/execution_optuna_iteration_0.py", line 49, in objective
    performance = evaluate_sequence_performance(heur, prob, num_agents=50, num_iterations=100, num_replicas=30)
                  ^^^^^^^^^^^^^^^^^^^^^^^^^^^^^^^^^^^^^^^^^^^^^^^^^^^^^^^^^^^^^^^^^^^^^^^^^^^^^^^^^^^^^^^^^^^^^
  File "/Users/valeriaenriquezlimon/Documents/research-llm/llm-metaheuristics/ollama_output_20241024_175417/execution_optuna_iteration_0.py", line 28, in evaluate_sequence_performance
    results_parallel = Parallel(n_jobs=num_cores)(delayed(run_metaheuristic)() for _ in range(num_replicas))
                       ^^^^^^^^^^^^^^^^^^^^^^^^^^^^^^^^^^^^^^^^^^^^^^^^^^^^^^^^^^^^^^^^^^^^^^^^^^^^^^^^^^^^^
  File "/Users/valeriaenriquezlimon/Documents/research-llm/.venv/lib/python3.12/site-packages/joblib/parallel.py", line 2007, in __call__
    return output if self.return_generator else list(output)
                                                ^^^^^^^^^^^^
  File "/Users/valeriaenriquezlimon/Documents/research-llm/.venv/lib/python3.12/site-packages/joblib/parallel.py", line 1650, in _get_outputs
    yield from self._retrieve()
  File "/Users/valeriaenriquezlimon/Documents/research-llm/.venv/lib/python3.12/site-packages/joblib/parallel.py", line 1754, in _retrieve
    self._raise_error_fast()
  File "/Users/valeriaenriquezlimon/Documents/research-llm/.venv/lib/python3.12/site-packages/joblib/parallel.py", line 1789, in _raise_error_fast
    error_job.get_result(self.timeout)
  File "/Users/valeriaenriquezlimon/Documents/research-llm/.venv/lib/python3.12/site-packages/joblib/parallel.py", line 745, in get_result
    return self._return_or_raise()
           ^^^^^^^^^^^^^^^^^^^^^^^
  File "/Users/valeriaenriquezlimon/Documents/research-llm/.venv/lib/python3.12/site-packages/joblib/parallel.py", line 763, in _return_or_raise
    raise self._result
operators.OperatorsError: Invalid distribution!
